Workbook

Sheet Dashboard
A1: TODAY'S DATE | C1: =TODAY() -> 44859 | E1: CURRENT TIME | G1: =TEXT(NOW(),"HH:MM:SS AM/PM") -> 10:47:24 am | I1: WEEKDAY: | J1: =UPPER(TEXT(C1,"dddd")) -> TUESDAY | L1: WEEK OF THE YEAR | M1: =_xlfn.ISOWEEKNUM(C1) -> 43 | O1: HQ Fleet Staff Attendance

Sheet Summary
A1: START DATE | B1: =DATEVALUE(TEXT('HQ Fleet Attendance'!B2,"dd/mm/yyyy")) -> 44741 | C1: =TEXT('HQ Fleet Attendance'!B2,"HH:MM:SS") -> 15:03:00 | D1: Week Name | E1: Month Name | F1: Month Number | G1: Week of the Year
A2: END DATE | B2: =TODAY() -> 44859 | C2: =TEXT(NOW(),"HH:MM:SS AM/PM") -> 10:47:24 am | D2: =TEXT(B2,"dddd") -> Tuesday | E2: =TEXT(B2,"mmmm") -> October | F2: =MONTH(B2) -> 10 | G2: =_xlfn.ISOWEEKNUM(B2) -> 43
A3: data-section1-activity | B3: All
A4: data-section1-position | B4: All
A5: ="CURRENT WEEK ANALYSIS OF "&UPPER($E$2) -> CURRENT WEEK ANALYSIS OF OCTOBER | N5: ="PREVIOUS WEEK ANALYSIS OF "&UPPER($E$2) -> PREVIOUS WEEK ANALYSIS OF OCTOBER | Y5: ="PREVIOUS MONTH ANALYSIS OF "&IF(MONTH($B$2)-1,VLOOKUP(MONTH($B$2)-1,'Month Guide'!$A:$B,2,0)) -> PREVIOUS MONTH ANALYSIS OF SEPTEMBER
A6: Staff Name | B6: Timestamp | C6: Date | D6: Monday | E6: Tuesday | F6: Wednesday | G6: Thursday | H6: Friday | I6: Saturday | J6: 6 Working Days % Tracker | K6: Days Present for that Month | L6: Attendance Staff Ranking | N6: =A$6 -> Staff Name | O6: =D$6 -> Monday | P6: =E$6 -> Tuesday | Q6: =F$6 -> Wednesday | R6: =G$6 -> Thursday | S6: =H$6 -> Friday | T6: =I$6 -> Saturday | U6: 6 Working Days % Tracker | V6: Days Present for that Month | W6: Attendance Staff Ranking | Y6: =N$6 -> Staff Name | Z6: =O$6 -> Monday | AA6: =P$6 -> Tuesday | AB6: =Q$6 -> Wednesday | AC6: =R$6 -> Thursday | AD6: =S$6 -> Friday | AE6: =T$6 -> Saturday | AF6: 6 Working Days % Tracker | AG6: Days Present for that Month | AH6: Attendance Staff Ranking
A7: abdulazeez_juwon | B7: =_xlfn.MAXIFS(HQ_Fleet_Attendance[data-end_time],HQ_Fleet_Attendance[data-section1-staff],Summary!A7) -> 44859.409 | C7: =_xlfn.MAXIFS('HQ Fleet Attendance'!P:P,'HQ Fleet Attendance'!E:E,Summary!A7) -> 44859 | D7: =IF(COUNTIFS('HQ Fleet Attendance'!Q:Q,Summary!$G$2,'HQ Fleet Attendance'!E:E,Summary!$A7,'HQ Fleet Attendance'!N:N,Summary!D$6)>0,"Present","Absent") -> Present | E7: =IF(COUNTIFS('HQ Fleet Attendance'!Q:Q,Summary!$G$2,'HQ Fleet Attendance'!E:E,Summary!$A7,'HQ Fleet Attendance'!N:N,Summary!E$6)>0,"Present","Absent") -> Present | F7: =IF(COUNTIFS('HQ Fleet Attendance'!Q:Q,Summary!$G$2,'HQ Fleet Attendance'!E:E,Summary!$A7,'HQ Fleet Attendance'!N:N,Summary!F$6)>0,"Present","Absent") -> Absent | G7: =IF(COUNTIFS('HQ Fleet Attendance'!Q:Q,Summary!$G$2,'HQ Fleet Attendance'!E:E,Summary!$A7,'HQ Fleet Attendance'!N:N,Summary!G$6)>0,"Present","Absent") -> Absent | H7: =IF(COUNTIFS('HQ Fleet Attendance'!Q:Q,Summary!$G$2,'HQ Fleet Attendance'!E:E,Summary!$A7,'HQ Fleet Attendance'!N:N,Summary!H$6)>0,"Present","Absent") -> Absent | I7: =IF(COUNTIFS('HQ Fleet Attendance'!Q:Q,Summary!$G$2,'HQ Fleet Attendance'!E:E,Summary!$A7,'HQ Fleet Attendance'!N:N,Summary!I$6)>0,"Present","Absent") -> Absent | J7: =IF(COUNTIF(D7:I7,"Present")=1,10%,IF(COUNTIF(D7:I7,"Present")=2,20%,IF(COUNTIF(D7:I7,"Present")=3,40%,IF(COUNTIF(D7:I7,"Present")=4,60%,IF(COUNTIF(D7:I7,"Present")=5,80%,IF(COUNTIF(D7:I7,"Present")=6,100%,0%)))))) -> 0.2 | K7: =COUNTIFS('HQ Fleet Attendance'!O:O,Summary!$F$2,'HQ Fleet Attendance'!E:E,Summary!A7) -> 12 | L7: =RANK(K7,K7:K19) -> 12 | N7: =A7 -> abdulazeez_juwon | O7: =IF(COUNTIFS('HQ Fleet Attendance'!$Q:$Q,Summary!$G$2-1,'HQ Fleet Attendance'!$E:$E,Summary!$A7,'HQ Fleet Attendance'!$N:$N,Summary!O$6)>0,"Present","Absent") -> Present | P7: =IF(COUNTIFS('HQ Fleet Attendance'!$Q:$Q,Summary!$G$2-1,'HQ Fleet Attendance'!$E:$E,Summary!$A7,'HQ Fleet Attendance'!$N:$N,Summary!P$6)>0,"Present","Absent") -> Present | Q7: =IF(COUNTIFS('HQ Fleet Attendance'!$Q:$Q,Summary!$G$2-1,'HQ Fleet Attendance'!$E:$E,Summary!$A7,'HQ Fleet Attendance'!$N:$N,Summary!Q$6)>0,"Present","Absent") -> Absent | R7: =IF(COUNTIFS('HQ Fleet Attendance'!$Q:$Q,Summary!$G$2-1,'HQ Fleet Attendance'!$E:$E,Summary!$A7,'HQ Fleet Attendance'!$N:$N,Summary!R$6)>0,"Present","Absent") -> Present | S7: =IF(COUNTIFS('HQ Fleet Attendance'!$Q:$Q,Summary!$G$2-1,'HQ Fleet Attendance'!$E:$E,Summary!$A7,'HQ Fleet Attendance'!$N:$N,Summary!S$6)>0,"Present","Absent") -> Present | T7: =IF(COUNTIFS('HQ Fleet Attendance'!$Q:$Q,Summary!$G$2-1,'HQ Fleet Attendance'!$E:$E,Summary!$A7,'HQ Fleet Attendance'!$N:$N,Summary!T$6)>0,"Present","Absent") -> Absent | U7: =IF(COUNTIF(O7:T7,"Present")=1,10%,IF(COUNTIF(O7:T7,"Present")=2,20%,IF(COUNTIF(O7:T7,"Present")=3,40%,IF(COUNTIF(O7:T7,"Present")=4,60%,IF(COUNTIF(O7:T7,"Present")=5,80%,IF(COUNTIF(O7:T7,"Present")=6,100%,0%)))))) -> 0.6 | V7: =COUNTIF(O7:T7,"Present") -> 4 | W7: =RANK(V7,V7:V19) -> 12 | Y7: =N7 -> abdulazeez_juwon | Z7: =IF(COUNTIFS('HQ Fleet Attendance'!$O:$O,Summary!$F$2-1,'HQ Fleet Attendance'!$E:$E,Summary!$Y7,'HQ Fleet Attendance'!$N:$N,Summary!Z$6)>0,"Present","Absent") -> Present | AA7: =IF(COUNTIFS('HQ Fleet Attendance'!$O:$O,Summary!$F$2-1,'HQ Fleet Attendance'!$E:$E,Summary!$Y7,'HQ Fleet Attendance'!$N:$N,Summary!AA$6)>0,"Present","Absent") -> Present | AB7: =IF(COUNTIFS('HQ Fleet Attendance'!$O:$O,Summary!$F$2-1,'HQ Fleet Attendance'!$E:$E,Summary!$Y7,'HQ Fleet Attendance'!$N:$N,Summary!AB$6)>0,"Present","Absent") -> Absent | AC7: =IF(COUNTIFS('HQ Fleet Attendance'!$O:$O,Summary!$F$2-1,'HQ Fleet Attendance'!$E:$E,Summary!$Y7,'HQ Fleet Attendance'!$N:$N,Summary!AC$6)>0,"Present","Absent") -> Present | AD7: =IF(COUNTIFS('HQ Fleet Attendance'!$O:$O,Summary!$F$2-1,'HQ Fleet Attendance'!$E:$E,Summary!$Y7,'HQ Fleet Attendance'!$N:$N,Summary!AD$6)>0,"Present","Absent") -> Present | AE7: =IF(COUNTIFS('HQ Fleet Attendance'!$O:$O,Summary!$F$2-1,'HQ Fleet Attendance'!$E:$E,Summary!$Y7,'HQ Fleet Attendance'!$N:$N,Summary!AE$6)>0,"Present","Absent") -> Absent | AF7: =IF(COUNTIF(Z7:AE7,"Present")=1,10%,IF(COUNTIF(Z7:AE7,"Present")=2,20%,IF(COUNTIF(Z7:AE7,"Present")=3,40%,IF(COUNTIF(Z7:AE7,"Present")=4,60%,IF(COUNTIF(Z7:AE7,"Present")=5,80%,IF(COUNTIF(Z7:AE7,"Present")=6,100%,0%)))))) -> 0.6 | AG7: =COUNTIFS('HQ Fleet Attendance'!$O:$O,Summary!$F$2-1,'HQ Fleet Attendance'!$E:$E,Summary!$Y7) -> 15 | AH7: =RANK(AG7,AG7:AG19) -> 12
A8: ademola_akintayo | B8: =_xlfn.MAXIFS(HQ_Fleet_Attendance[data-end_time],HQ_Fleet_Attendance[data-section1-staff],Summary!A8) -> 44859.408 | C8: =_xlfn.MAXIFS('HQ Fleet Attendance'!P:P,'HQ Fleet Attendance'!E:E,Summary!A8) -> 44859 | D8: =IF(COUNTIFS('HQ Fleet Attendance'!Q:Q,Summary!$G$2,'HQ Fleet Attendance'!E:E,Summary!$A8,'HQ Fleet Attendance'!N:N,Summary!D$6)>0,"Present","Absent") -> Present | E8: =IF(COUNTIFS('HQ Fleet Attendance'!Q:Q,Summary!$G$2,'HQ Fleet Attendance'!E:E,Summary!$A8,'HQ Fleet Attendance'!N:N,Summary!E$6)>0,"Present","Absent") -> Present | F8: =IF(COUNTIFS('HQ Fleet Attendance'!Q:Q,Summary!$G$2,'HQ Fleet Attendance'!E:E,Summary!$A8,'HQ Fleet Attendance'!N:N,Summary!F$6)>0,"Present","Absent") -> Absent | G8: =IF(COUNTIFS('HQ Fleet Attendance'!Q:Q,Summary!$G$2,'HQ Fleet Attendance'!E:E,Summary!$A8,'HQ Fleet Attendance'!N:N,Summary!G$6)>0,"Present","Absent") -> Absent | H8: =IF(COUNTIFS('HQ Fleet Attendance'!Q:Q,Summary!$G$2,'HQ Fleet Attendance'!E:E,Summary!$A8,'HQ Fleet Attendance'!N:N,Summary!H$6)>0,"Present","Absent") -> Absent | I8: =IF(COUNTIFS('HQ Fleet Attendance'!Q:Q,Summary!$G$2,'HQ Fleet Attendance'!E:E,Summary!$A8,'HQ Fleet Attendance'!N:N,Summary!I$6)>0,"Present","Absent") -> Absent | J8: =IF(COUNTIF(D8:I8,"Present")=1,10%,IF(COUNTIF(D8:I8,"Present")=2,20%,IF(COUNTIF(D8:I8,"Present")=3,40%,IF(COUNTIF(D8:I8,"Present")=4,60%,IF(COUNTIF(D8:I8,"Present")=5,80%,IF(COUNTIF(D8:I8,"Present")=6,100%,0%)))))) -> 0.2 | K8: =COUNTIFS('HQ Fleet Attendance'!O:O,Summary!$F$2,'HQ Fleet Attendance'!E:E,Summary!A8) -> 19 | L8: =RANK(K8,K8:K20) -> 1 | N8: =A8 -> ademola_akintayo | O8: =IF(COUNTIFS('HQ Fleet Attendance'!$Q:$Q,Summary!$G$2-1,'HQ Fleet Attendance'!$E:$E,Summary!$A8,'HQ Fleet Attendance'!$N:$N,Summary!O$6)>0,"Present","Absent") -> Present | P8: =IF(COUNTIFS('HQ Fleet Attendance'!$Q:$Q,Summary!$G$2-1,'HQ Fleet Attendance'!$E:$E,Summary!$A8,'HQ Fleet Attendance'!$N:$N,Summary!P$6)>0,"Present","Absent") -> Present | Q8: =IF(COUNTIFS('HQ Fleet Attendance'!$Q:$Q,Summary!$G$2-1,'HQ Fleet Attendance'!$E:$E,Summary!$A8,'HQ Fleet Attendance'!$N:$N,Summary!Q$6)>0,"Present","Absent") -> Present | R8: =IF(COUNTIFS('HQ Fleet Attendance'!$Q:$Q,Summary!$G$2-1,'HQ Fleet Attendance'!$E:$E,Summary!$A8,'HQ Fleet Attendance'!$N:$N,Summary!R$6)>0,"Present","Absent") -> Present | S8: =IF(COUNTIFS('HQ Fleet Attendance'!$Q:$Q,Summary!$G$2-1,'HQ Fleet Attendance'!$E:$E,Summary!$A8,'HQ Fleet Attendance'!$N:$N,Summary!S$6)>0,"Present","Absent") -> Present | T8: =IF(COUNTIFS('HQ Fleet Attendance'!$Q:$Q,Summary!$G$2-1,'HQ Fleet Attendance'!$E:$E,Summary!$A8,'HQ Fleet Attendance'!$N:$N,Summary!T$6)>0,"Present","Absent") -> Present | U8: =IF(COUNTIF(O8:T8,"Present")=1,10%,IF(COUNTIF(O8:T8,"Present")=2,20%,IF(COUNTIF(O8:T8,"Present")=3,40%,IF(COUNTIF(O8:T8,"Present")=4,60%,IF(COUNTIF(O8:T8,"Present")=5,80%,IF(COUNTIF(O8:T8,"Present")=6,100%,0%)))))) -> 1 | V8: =COUNTIF(O8:T8,"Present") -> 6 | W8: =RANK(V8,V8:V20) -> 1 | Y8: =N8 -> ademola_akintayo | Z8: =IF(COUNTIFS('HQ Fleet Attendance'!$O:$O,Summary!$F$2-1,'HQ Fleet Attendance'!$E:$E,Summary!$Y8,'HQ Fleet Attendance'!$N:$N,Summary!Z$6)>0,"Present","Absent") -> Present | AA8: =IF(COUNTIFS('HQ Fleet Attendance'!$O:$O,Summary!$F$2-1,'HQ Fleet Attendance'!$E:$E,Summary!$Y8,'HQ Fleet Attendance'!$N:$N,Summary!AA$6)>0,"Present","Absent") -> Present | AB8: =IF(COUNTIFS('HQ Fleet Attendance'!$O:$O,Summary!$F$2-1,'HQ Fleet Attendance'!$E:$E,Summary!$Y8,'HQ Fleet Attendance'!$N:$N,Summary!AB$6)>0,"Present","Absent") -> Present | AC8: =IF(COUNTIFS('HQ Fleet Attendance'!$O:$O,Summary!$F$2-1,'HQ Fleet Attendance'!$E:$E,Summary!$Y8,'HQ Fleet Attendance'!$N:$N,Summary!AC$6)>0,"Present","Absent") -> Present | AD8: =IF(COUNTIFS('HQ Fleet Attendance'!$O:$O,Summary!$F$2-1,'HQ Fleet Attendance'!$E:$E,Summary!$Y8,'HQ Fleet Attendance'!$N:$N,Summary!AD$6)>0,"Present","Absent") -> Present | AE8: =IF(COUNTIFS('HQ Fleet Attendance'!$O:$O,Summary!$F$2-1,'HQ Fleet Attendance'!$E:$E,Summary!$Y8,'HQ Fleet Attendance'!$N:$N,Summary!AE$6)>0,"Present","Absent") -> Present | AF8: =IF(COUNTIF(Z8:AE8,"Present")=1,10%,IF(COUNTIF(Z8:AE8,"Present")=2,20%,IF(COUNTIF(Z8:AE8,"Present")=3,40%,IF(COUNTIF(Z8:AE8,"Present")=4,60%,IF(COUNTIF(Z8:AE8,"Present")=5,80%,IF(COUNTIF(Z8:AE8,"Present")=6,100%,0%)))))) -> 1 | AG8: =COUNTIFS('HQ Fleet Attendance'!$O:$O,Summary!$F$2-1,'HQ Fleet Attendance'!$E:$E,Summary!$Y8) -> 25 | AH8: =RANK(AG8,AG8:AG20) -> 2
A9: ayo_bamidele | B9: =_xlfn.MAXIFS(HQ_Fleet_Attendance[data-end_time],HQ_Fleet_Attendance[data-section1-staff],Summary!A9) -> 44859.408 | C9: =_xlfn.MAXIFS('HQ Fleet Attendance'!P:P,'HQ Fleet Attendance'!E:E,Summary!A9) -> 44859 | D9: =IF(COUNTIFS('HQ Fleet Attendance'!Q:Q,Summary!$G$2,'HQ Fleet Attendance'!E:E,Summary!$A9,'HQ Fleet Attendance'!N:N,Summary!D$6)>0,"Present","Absent") -> Present | E9: =IF(COUNTIFS('HQ Fleet Attendance'!Q:Q,Summary!$G$2,'HQ Fleet Attendance'!E:E,Summary!$A9,'HQ Fleet Attendance'!N:N,Summary!E$6)>0,"Present","Absent") -> Present | F9: =IF(COUNTIFS('HQ Fleet Attendance'!Q:Q,Summary!$G$2,'HQ Fleet Attendance'!E:E,Summary!$A9,'HQ Fleet Attendance'!N:N,Summary!F$6)>0,"Present","Absent") -> Absent | G9: =IF(COUNTIFS('HQ Fleet Attendance'!Q:Q,Summary!$G$2,'HQ Fleet Attendance'!E:E,Summary!$A9,'HQ Fleet Attendance'!N:N,Summary!G$6)>0,"Present","Absent") -> Absent | H9: =IF(COUNTIFS('HQ Fleet Attendance'!Q:Q,Summary!$G$2,'HQ Fleet Attendance'!E:E,Summary!$A9,'HQ Fleet Attendance'!N:N,Summary!H$6)>0,"Present","Absent") -> Absent | I9: =IF(COUNTIFS('HQ Fleet Attendance'!Q:Q,Summary!$G$2,'HQ Fleet Attendance'!E:E,Summary!$A9,'HQ Fleet Attendance'!N:N,Summary!I$6)>0,"Present","Absent") -> Absent | J9: =IF(COUNTIF(D9:I9,"Present")=1,10%,IF(COUNTIF(D9:I9,"Present")=2,20%,IF(COUNTIF(D9:I9,"Present")=3,40%,IF(COUNTIF(D9:I9,"Present")=4,60%,IF(COUNTIF(D9:I9,"Present")=5,80%,IF(COUNTIF(D9:I9,"Present")=6,100%,0%)))))) -> 0.2 | K9: =COUNTIFS('HQ Fleet Attendance'!O:O,Summary!$F$2,'HQ Fleet Attendance'!E:E,Summary!A9) -> 19 | L9: =RANK(K9,K9:K21) -> 1 | N9: =A9 -> ayo_bamidele | O9: =IF(COUNTIFS('HQ Fleet Attendance'!$Q:$Q,Summary!$G$2-1,'HQ Fleet Attendance'!$E:$E,Summary!$A9,'HQ Fleet Attendance'!$N:$N,Summary!O$6)>0,"Present","Absent") -> Present | P9: =IF(COUNTIFS('HQ Fleet Attendance'!$Q:$Q,Summary!$G$2-1,'HQ Fleet Attendance'!$E:$E,Summary!$A9,'HQ Fleet Attendance'!$N:$N,Summary!P$6)>0,"Present","Absent") -> Present | Q9: =IF(COUNTIFS('HQ Fleet Attendance'!$Q:$Q,Summary!$G$2-1,'HQ Fleet Attendance'!$E:$E,Summary!$A9,'HQ Fleet Attendance'!$N:$N,Summary!Q$6)>0,"Present","Absent") -> Present | R9: =IF(COUNTIFS('HQ Fleet Attendance'!$Q:$Q,Summary!$G$2-1,'HQ Fleet Attendance'!$E:$E,Summary!$A9,'HQ Fleet Attendance'!$N:$N,Summary!R$6)>0,"Present","Absent") -> Present | S9: =IF(COUNTIFS('HQ Fleet Attendance'!$Q:$Q,Summary!$G$2-1,'HQ Fleet Attendance'!$E:$E,Summary!$A9,'HQ Fleet Attendance'!$N:$N,Summary!S$6)>0,"Present","Absent") -> Present | T9: =IF(COUNTIFS('HQ Fleet Attendance'!$Q:$Q,Summary!$G$2-1,'HQ Fleet Attendance'!$E:$E,Summary!$A9,'HQ Fleet Attendance'!$N:$N,Summary!T$6)>0,"Present","Absent") -> Present | U9: =IF(COUNTIF(O9:T9,"Present")=1,10%,IF(COUNTIF(O9:T9,"Present")=2,20%,IF(COUNTIF(O9:T9,"Present")=3,40%,IF(COUNTIF(O9:T9,"Present")=4,60%,IF(COUNTIF(O9:T9,"Present")=5,80%,IF(COUNTIF(O9:T9,"Present")=6,100%,0%)))))) -> 1 | V9: =COUNTIF(O9:T9,"Present") -> 6 | W9: =RANK(V9,V9:V21) -> 1 | Y9: =N9 -> ayo_bamidele | Z9: =IF(COUNTIFS('HQ Fleet Attendance'!$O:$O,Summary!$F$2-1,'HQ Fleet Attendance'!$E:$E,Summary!$Y9,'HQ Fleet Attendance'!$N:$N,Summary!Z$6)>0,"Present","Absent") -> Present | AA9: =IF(COUNTIFS('HQ Fleet Attendance'!$O:$O,Summary!$F$2-1,'HQ Fleet Attendance'!$E:$E,Summary!$Y9,'HQ Fleet Attendance'!$N:$N,Summary!AA$6)>0,"Present","Absent") -> Present | AB9: =IF(COUNTIFS('HQ Fleet Attendance'!$O:$O,Summary!$F$2-1,'HQ Fleet Attendance'!$E:$E,Summary!$Y9,'HQ Fleet Attendance'!$N:$N,Summary!AB$6)>0,"Present","Absent") -> Present | AC9: =IF(COUNTIFS('HQ Fleet Attendance'!$O:$O,Summary!$F$2-1,'HQ Fleet Attendance'!$E:$E,Summary!$Y9,'HQ Fleet Attendance'!$N:$N,Summary!AC$6)>0,"Present","Absent") -> Present | AD9: =IF(COUNTIFS('HQ Fleet Attendance'!$O:$O,Summary!$F$2-1,'HQ Fleet Attendance'!$E:$E,Summary!$Y9,'HQ Fleet Attendance'!$N:$N,Summary!AD$6)>0,"Present","Absent") -> Present | AE9: =IF(COUNTIFS('HQ Fleet Attendance'!$O:$O,Summary!$F$2-1,'HQ Fleet Attendance'!$E:$E,Summary!$Y9,'HQ Fleet Attendance'!$N:$N,Summary!AE$6)>0,"Present","Absent") -> Present | AF9: =IF(COUNTIF(Z9:AE9,"Present")=1,10%,IF(COUNTIF(Z9:AE9,"Present")=2,20%,IF(COUNTIF(Z9:AE9,"Present")=3,40%,IF(COUNTIF(Z9:AE9,"Present")=4,60%,IF(COUNTIF(Z9:AE9,"Present")=5,80%,IF(COUNTIF(Z9:AE9,"Present")=6,100%,0%)))))) -> 1 | AG9: =COUNTIFS('HQ Fleet Attendance'!$O:$O,Summary!$F$2-1,'HQ Fleet Attendance'!$E:$E,Summary!$Y9) -> 22 | AH9: =RANK(AG9,AG9:AG21) -> 7
A10: babatunde_afeez | B10: =_xlfn.MAXIFS(HQ_Fleet_Attendance[data-end_time],HQ_Fleet_Attendance[data-section1-staff],Summary!A10) -> 44859.408 | C10: =_xlfn.MAXIFS('HQ Fleet Attendance'!P:P,'HQ Fleet Attendance'!E:E,Summary!A10) -> 44859 | D10: =IF(COUNTIFS('HQ Fleet Attendance'!Q:Q,Summary!$G$2,'HQ Fleet Attendance'!E:E,Summary!$A10,'HQ Fleet Attendance'!N:N,Summary!D$6)>0,"Present","Absent") -> Present | E10: =IF(COUNTIFS('HQ Fleet Attendance'!Q:Q,Summary!$G$2,'HQ Fleet Attendance'!E:E,Summary!$A10,'HQ Fleet Attendance'!N:N,Summary!E$6)>0,"Present","Absent") -> Present | F10: =IF(COUNTIFS('HQ Fleet Attendance'!Q:Q,Summary!$G$2,'HQ Fleet Attendance'!E:E,Summary!$A10,'HQ Fleet Attendance'!N:N,Summary!F$6)>0,"Present","Absent") -> Absent | G10: =IF(COUNTIFS('HQ Fleet Attendance'!Q:Q,Summary!$G$2,'HQ Fleet Attendance'!E:E,Summary!$A10,'HQ Fleet Attendance'!N:N,Summary!G$6)>0,"Present","Absent") -> Absent | H10: =IF(COUNTIFS('HQ Fleet Attendance'!Q:Q,Summary!$G$2,'HQ Fleet Attendance'!E:E,Summary!$A10,'HQ Fleet Attendance'!N:N,Summary!H$6)>0,"Present","Absent") -> Absent | I10: =IF(COUNTIFS('HQ Fleet Attendance'!Q:Q,Summary!$G$2,'HQ Fleet Attendance'!E:E,Summary!$A10,'HQ Fleet Attendance'!N:N,Summary!I$6)>0,"Present","Absent") -> Absent | J10: =IF(COUNTIF(D10:I10,"Present")=1,10%,IF(COUNTIF(D10:I10,"Present")=2,20%,IF(COUNTIF(D10:I10,"Present")=3,40%,IF(COUNTIF(D10:I10,"Present")=4,60%,IF(COUNTIF(D10:I10,"Present")=5,80%,IF(COUNTIF(D10:I10,"Present")=6,100%,0%)))))) -> 0.2 | K10: =COUNTIFS('HQ Fleet Attendance'!O:O,Summary!$F$2,'HQ Fleet Attendance'!E:E,Summary!A10) -> 16 | L10: =RANK(K10,K10:K22) -> 6 | N10: =A10 -> babatunde_afeez | O10: =IF(COUNTIFS('HQ Fleet Attendance'!$Q:$Q,Summary!$G$2-1,'HQ Fleet Attendance'!$E:$E,Summary!$A10,'HQ Fleet Attendance'!$N:$N,Summary!O$6)>0,"Present","Absent") -> Present | P10: =IF(COUNTIFS('HQ Fleet Attendance'!$Q:$Q,Summary!$G$2-1,'HQ Fleet Attendance'!$E:$E,Summary!$A10,'HQ Fleet Attendance'!$N:$N,Summary!P$6)>0,"Present","Absent") -> Present | Q10: =IF(COUNTIFS('HQ Fleet Attendance'!$Q:$Q,Summary!$G$2-1,'HQ Fleet Attendance'!$E:$E,Summary!$A10,'HQ Fleet Attendance'!$N:$N,Summary!Q$6)>0,"Present","Absent") -> Present | R10: =IF(COUNTIFS('HQ Fleet Attendance'!$Q:$Q,Summary!$G$2-1,'HQ Fleet Attendance'!$E:$E,Summary!$A10,'HQ Fleet Attendance'!$N:$N,Summary!R$6)>0,"Present","Absent") -> Present | S10: =IF(COUNTIFS('HQ Fleet Attendance'!$Q:$Q,Summary!$G$2-1,'HQ Fleet Attendance'!$E:$E,Summary!$A10,'HQ Fleet Attendance'!$N:$N,Summary!S$6)>0,"Present","Absent") -> Present | T10: =IF(COUNTIFS('HQ Fleet Attendance'!$Q:$Q,Summary!$G$2-1,'HQ Fleet Attendance'!$E:$E,Summary!$A10,'HQ Fleet Attendance'!$N:$N,Summary!T$6)>0,"Present","Absent") -> Absent | U10: =IF(COUNTIF(O10:T10,"Present")=1,10%,IF(COUNTIF(O10:T10,"Present")=2,20%,IF(COUNTIF(O10:T10,"Present")=3,40%,IF(COUNTIF(O10:T10,"Present")=4,60%,IF(COUNTIF(O10:T10,"Present")=5,80%,IF(COUNTIF(O10:T10,"Present")=6,100%,0%)))))) -> 0.8 | V10: =COUNTIF(O10:T10,"Present") -> 5 | W10: =RANK(V10,V10:V22) -> 8 | Y10: =N10 -> babatunde_afeez | Z10: =IF(COUNTIFS('HQ Fleet Attendance'!$O:$O,Summary!$F$2-1,'HQ Fleet Attendance'!$E:$E,Summary!$Y10,'HQ Fleet Attendance'!$N:$N,Summary!Z$6)>0,"Present","Absent") -> Present | AA10: =IF(COUNTIFS('HQ Fleet Attendance'!$O:$O,Summary!$F$2-1,'HQ Fleet Attendance'!$E:$E,Summary!$Y10,'HQ Fleet Attendance'!$N:$N,Summary!AA$6)>0,"Present","Absent") -> Present | AB10: =IF(COUNTIFS('HQ Fleet Attendance'!$O:$O,Summary!$F$2-1,'HQ Fleet Attendance'!$E:$E,Summary!$Y10,'HQ Fleet Attendance'!$N:$N,Summary!AB$6)>0,"Present","Absent") -> Present | AC10: =IF(COUNTIFS('HQ Fleet Attendance'!$O:$O,Summary!$F$2-1,'HQ Fleet Attendance'!$E:$E,Summary!$Y10,'HQ Fleet Attendance'!$N:$N,Summary!AC$6)>0,"Present","Absent") -> Present | AD10: =IF(COUNTIFS('HQ Fleet Attendance'!$O:$O,Summary!$F$2-1,'HQ Fleet Attendance'!$E:$E,Summary!$Y10,'HQ Fleet Attendance'!$N:$N,Summary!AD$6)>0,"Present","Absent") -> Present | AE10: =IF(COUNTIFS('HQ Fleet Attendance'!$O:$O,Summary!$F$2-1,'HQ Fleet Attendance'!$E:$E,Summary!$Y10,'HQ Fleet Attendance'!$N:$N,Summary!AE$6)>0,"Present","Absent") -> Present | AF10: =IF(COUNTIF(Z10:AE10,"Present")=1,10%,IF(COUNTIF(Z10:AE10,"Present")=2,20%,IF(COUNTIF(Z10:AE10,"Present")=3,40%,IF(COUNTIF(Z10:AE10,"Present")=4,60%,IF(COUNTIF(Z10:AE10,"Present")=5,80%,IF(COUNTIF(Z10:AE10,"Present")=6,100%,0%)))))) -> 1 | AG10: =COUNTIFS('HQ Fleet Attendance'!$O:$O,Summary!$F$2-1,'HQ Fleet Attendance'!$E:$E,Summary!$Y10) -> 18 | AH10: =RANK(AG10,AG10:AG22) -> 9
A11: chibuzo_nwankwo | B11: =_xlfn.MAXIFS(HQ_Fleet_Attendance[data-end_time],HQ_Fleet_Attendance[data-section1-staff],Summary!A11) -> 44859.408 | C11: =_xlfn.MAXIFS('HQ Fleet Attendance'!P:P,'HQ Fleet Attendance'!E:E,Summary!A11) -> 44859 | D11: =IF(COUNTIFS('HQ Fleet Attendance'!Q:Q,Summary!$G$2,'HQ Fleet Attendance'!E:E,Summary!$A11,'HQ Fleet Attendance'!N:N,Summary!D$6)>0,"Present","Absent") -> Present | E11: =IF(COUNTIFS('HQ Fleet Attendance'!Q:Q,Summary!$G$2,'HQ Fleet Attendance'!E:E,Summary!$A11,'HQ Fleet Attendance'!N:N,Summary!E$6)>0,"Present","Absent") -> Present | F11: =IF(COUNTIFS('HQ Fleet Attendance'!Q:Q,Summary!$G$2,'HQ Fleet Attendance'!E:E,Summary!$A11,'HQ Fleet Attendance'!N:N,Summary!F$6)>0,"Present","Absent") -> Absent | G11: =IF(COUNTIFS('HQ Fleet Attendance'!Q:Q,Summary!$G$2,'HQ Fleet Attendance'!E:E,Summary!$A11,'HQ Fleet Attendance'!N:N,Summary!G$6)>0,"Present","Absent") -> Absent | H11: =IF(COUNTIFS('HQ Fleet Attendance'!Q:Q,Summary!$G$2,'HQ Fleet Attendance'!E:E,Summary!$A11,'HQ Fleet Attendance'!N:N,Summary!H$6)>0,"Present","Absent") -> Absent | I11: =IF(COUNTIFS('HQ Fleet Attendance'!Q:Q,Summary!$G$2,'HQ Fleet Attendance'!E:E,Summary!$A11,'HQ Fleet Attendance'!N:N,Summary!I$6)>0,"Present","Absent") -> Absent | J11: =IF(COUNTIF(D11:I11,"Present")=1,10%,IF(COUNTIF(D11:I11,"Present")=2,20%,IF(COUNTIF(D11:I11,"Present")=3,40%,IF(COUNTIF(D11:I11,"Present")=4,60%,IF(COUNTIF(D11:I11,"Present")=5,80%,IF(COUNTIF(D11:I11,"Present")=6,100%,0%)))))) -> 0.2 | K11: =COUNTIFS('HQ Fleet Attendance'!O:O,Summary!$F$2,'HQ Fleet Attendance'!E:E,Summary!A11) -> 15 | L11: =RANK(K11,K11:K23) -> 6 | N11: =A11 -> chibuzo_nwankwo | O11: =IF(COUNTIFS('HQ Fleet Attendance'!$Q:$Q,Summary!$G$2-1,'HQ Fleet Attendance'!$E:$E,Summary!$A11,'HQ Fleet Attendance'!$N:$N,Summary!O$6)>0,"Present","Absent") -> Present | P11: =IF(COUNTIFS('HQ Fleet Attendance'!$Q:$Q,Summary!$G$2-1,'HQ Fleet Attendance'!$E:$E,Summary!$A11,'HQ Fleet Attendance'!$N:$N,Summary!P$6)>0,"Present","Absent") -> Present | Q11: =IF(COUNTIFS('HQ Fleet Attendance'!$Q:$Q,Summary!$G$2-1,'HQ Fleet Attendance'!$E:$E,Summary!$A11,'HQ Fleet Attendance'!$N:$N,Summary!Q$6)>0,"Present","Absent") -> Present | R11: =IF(COUNTIFS('HQ Fleet Attendance'!$Q:$Q,Summary!$G$2-1,'HQ Fleet Attendance'!$E:$E,Summary!$A11,'HQ Fleet Attendance'!$N:$N,Summary!R$6)>0,"Present","Absent") -> Present | S11: =IF(COUNTIFS('HQ Fleet Attendance'!$Q:$Q,Summary!$G$2-1,'HQ Fleet Attendance'!$E:$E,Summary!$A11,'HQ Fleet Attendance'!$N:$N,Summary!S$6)>0,"Present","Absent") -> Present | T11: =IF(COUNTIFS('HQ Fleet Attendance'!$Q:$Q,Summary!$G$2-1,'HQ Fleet Attendance'!$E:$E,Summary!$A11,'HQ Fleet Attendance'!$N:$N,Summary!T$6)>0,"Present","Absent") -> Present | U11: =IF(COUNTIF(O11:T11,"Present")=1,10%,IF(COUNTIF(O11:T11,"Present")=2,20%,IF(COUNTIF(O11:T11,"Present")=3,40%,IF(COUNTIF(O11:T11,"Present")=4,60%,IF(COUNTIF(O11:T11,"Present")=5,80%,IF(COUNTIF(O11:T11,"Present")=6,100%,0%)))))) -> 1 | V11: =COUNTIF(O11:T11,"Present") -> 6 | W11: =RANK(V11,V11:V23) -> 1 | Y11: =N11 -> chibuzo_nwankwo | Z11: =IF(COUNTIFS('HQ Fleet Attendance'!$O:$O,Summary!$F$2-1,'HQ Fleet Attendance'!$E:$E,Summary!$Y11,'HQ Fleet Attendance'!$N:$N,Summary!Z$6)>0,"Present","Absent") -> Present | AA11: =IF(COUNTIFS('HQ Fleet Attendance'!$O:$O,Summary!$F$2-1,'HQ Fleet Attendance'!$E:$E,Summary!$Y11,'HQ Fleet Attendance'!$N:$N,Summary!AA$6)>0,"Present","Absent") -> Present | AB11: =IF(COUNTIFS('HQ Fleet Attendance'!$O:$O,Summary!$F$2-1,'HQ Fleet Attendance'!$E:$E,Summary!$Y11,'HQ Fleet Attendance'!$N:$N,Summary!AB$6)>0,"Present","Absent") -> Present | AC11: =IF(COUNTIFS('HQ Fleet Attendance'!$O:$O,Summary!$F$2-1,'HQ Fleet Attendance'!$E:$E,Summary!$Y11,'HQ Fleet Attendance'!$N:$N,Summary!AC$6)>0,"Present","Absent") -> Present | AD11: =IF(COUNTIFS('HQ Fleet Attendance'!$O:$O,Summary!$F$2-1,'HQ Fleet Attendance'!$E:$E,Summary!$Y11,'HQ Fleet Attendance'!$N:$N,Summary!AD$6)>0,"Present","Absent") -> Present | AE11: =IF(COUNTIFS('HQ Fleet Attendance'!$O:$O,Summary!$F$2-1,'HQ Fleet Attendance'!$E:$E,Summary!$Y11,'HQ Fleet Attendance'!$N:$N,Summary!AE$6)>0,"Present","Absent") -> Present | AF11: =IF(COUNTIF(Z11:AE11,"Present")=1,10%,IF(COUNTIF(Z11:AE11,"Present")=2,20%,IF(COUNTIF(Z11:AE11,"Present")=3,40%,IF(COUNTIF(Z11:AE11,"Present")=4,60%,IF(COUNTIF(Z11:AE11,"Present")=5,80%,IF(COUNTIF(Z11:AE11,"Present")=6,100%,0%)))))) -> 1 | AG11: =COUNTIFS('HQ Fleet Attendance'!$O:$O,Summary!$F$2-1,'HQ Fleet Attendance'!$E:$E,Summary!$Y11) -> 24 | AH11: =RANK(AG11,AG11:AG23) -> 4
A12: david_jimba | B12: =_xlfn.MAXIFS(HQ_Fleet_Attendance[data-end_time],HQ_Fleet_Attendance[data-section1-staff],Summary!A12) -> 44859.408 | C12: =_xlfn.MAXIFS('HQ Fleet Attendance'!P:P,'HQ Fleet Attendance'!E:E,Summary!A12) -> 44859 | D12: =IF(COUNTIFS('HQ Fleet Attendance'!Q:Q,Summary!$G$2,'HQ Fleet Attendance'!E:E,Summary!$A12,'HQ Fleet Attendance'!N:N,Summary!D$6)>0,"Present","Absent") -> Present | E12: =IF(COUNTIFS('HQ Fleet Attendance'!Q:Q,Summary!$G$2,'HQ Fleet Attendance'!E:E,Summary!$A12,'HQ Fleet Attendance'!N:N,Summary!E$6)>0,"Present","Absent") -> Present | F12: =IF(COUNTIFS('HQ Fleet Attendance'!Q:Q,Summary!$G$2,'HQ Fleet Attendance'!E:E,Summary!$A12,'HQ Fleet Attendance'!N:N,Summary!F$6)>0,"Present","Absent") -> Absent | G12: =IF(COUNTIFS('HQ Fleet Attendance'!Q:Q,Summary!$G$2,'HQ Fleet Attendance'!E:E,Summary!$A12,'HQ Fleet Attendance'!N:N,Summary!G$6)>0,"Present","Absent") -> Absent | H12: =IF(COUNTIFS('HQ Fleet Attendance'!Q:Q,Summary!$G$2,'HQ Fleet Attendance'!E:E,Summary!$A12,'HQ Fleet Attendance'!N:N,Summary!H$6)>0,"Present","Absent") -> Absent | I12: =IF(COUNTIFS('HQ Fleet Attendance'!Q:Q,Summary!$G$2,'HQ Fleet Attendance'!E:E,Summary!$A12,'HQ Fleet Attendance'!N:N,Summary!I$6)>0,"Present","Absent") -> Absent | J12: =IF(COUNTIF(D12:I12,"Present")=1,10%,IF(COUNTIF(D12:I12,"Present")=2,20%,IF(COUNTIF(D12:I12,"Present")=3,40%,IF(COUNTIF(D12:I12,"Present")=4,60%,IF(COUNTIF(D12:I12,"Present")=5,80%,IF(COUNTIF(D12:I12,"Present")=6,100%,0%)))))) -> 0.2 | K12: =COUNTIFS('HQ Fleet Attendance'!O:O,Summary!$F$2,'HQ Fleet Attendance'!E:E,Summary!A12) -> 19 | L12: =RANK(K12,K12:K24) -> 1 | N12: =A12 -> david_jimba | O12: =IF(COUNTIFS('HQ Fleet Attendance'!$Q:$Q,Summary!$G$2-1,'HQ Fleet Attendance'!$E:$E,Summary!$A12,'HQ Fleet Attendance'!$N:$N,Summary!O$6)>0,"Present","Absent") -> Present | P12: =IF(COUNTIFS('HQ Fleet Attendance'!$Q:$Q,Summary!$G$2-1,'HQ Fleet Attendance'!$E:$E,Summary!$A12,'HQ Fleet Attendance'!$N:$N,Summary!P$6)>0,"Present","Absent") -> Present | Q12: =IF(COUNTIFS('HQ Fleet Attendance'!$Q:$Q,Summary!$G$2-1,'HQ Fleet Attendance'!$E:$E,Summary!$A12,'HQ Fleet Attendance'!$N:$N,Summary!Q$6)>0,"Present","Absent") -> Present | R12: =IF(COUNTIFS('HQ Fleet Attendance'!$Q:$Q,Summary!$G$2-1,'HQ Fleet Attendance'!$E:$E,Summary!$A12,'HQ Fleet Attendance'!$N:$N,Summary!R$6)>0,"Present","Absent") -> Present | S12: =IF(COUNTIFS('HQ Fleet Attendance'!$Q:$Q,Summary!$G$2-1,'HQ Fleet Attendance'!$E:$E,Summary!$A12,'HQ Fleet Attendance'!$N:$N,Summary!S$6)>0,"Present","Absent") -> Present | T12: =IF(COUNTIFS('HQ Fleet Attendance'!$Q:$Q,Summary!$G$2-1,'HQ Fleet Attendance'!$E:$E,Summary!$A12,'HQ Fleet Attendance'!$N:$N,Summary!T$6)>0,"Present","Absent") -> Present | U12: =IF(COUNTIF(O12:T12,"Present")=1,10%,IF(COUNTIF(O12:T12,"Present")=2,20%,IF(COUNTIF(O12:T12,"Present")=3,40%,IF(COUNTIF(O12:T12,"Present")=4,60%,IF(COUNTIF(O12:T12,"Present")=5,80%,IF(COUNTIF(O12:T12,"Present")=6,100%,0%)))))) -> 1 | V12: =COUNTIF(O12:T12,"Present") -> 6 | W12: =RANK(V12,V12:V24) -> 1 | Y12: =N12 -> david_jimba | Z12: =IF(COUNTIFS('HQ Fleet Attendance'!$O:$O,Summary!$F$2-1,'HQ Fleet Attendance'!$E:$E,Summary!$Y12,'HQ Fleet Attendance'!$N:$N,Summary!Z$6)>0,"Present","Absent") -> Present | AA12: =IF(COUNTIFS('HQ Fleet Attendance'!$O:$O,Summary!$F$2-1,'HQ Fleet Attendance'!$E:$E,Summary!$Y12,'HQ Fleet Attendance'!$N:$N,Summary!AA$6)>0,"Present","Absent") -> Present | AB12: =IF(COUNTIFS('HQ Fleet Attendance'!$O:$O,Summary!$F$2-1,'HQ Fleet Attendance'!$E:$E,Summary!$Y12,'HQ Fleet Attendance'!$N:$N,Summary!AB$6)>0,"Present","Absent") -> Present | AC12: =IF(COUNTIFS('HQ Fleet Attendance'!$O:$O,Summary!$F$2-1,'HQ Fleet Attendance'!$E:$E,Summary!$Y12,'HQ Fleet Attendance'!$N:$N,Summary!AC$6)>0,"Present","Absent") -> Present | AD12: =IF(COUNTIFS('HQ Fleet Attendance'!$O:$O,Summary!$F$2-1,'HQ Fleet Attendance'!$E:$E,Summary!$Y12,'HQ Fleet Attendance'!$N:$N,Summary!AD$6)>0,"Present","Absent") -> Present | AE12: =IF(COUNTIFS('HQ Fleet Attendance'!$O:$O,Summary!$F$2-1,'HQ Fleet Attendance'!$E:$E,Summary!$Y12,'HQ Fleet Attendance'!$N:$N,Summary!AE$6)>0,"Present","Absent") -> Present | AF12: =IF(COUNTIF(Z12:AE12,"Present")=1,10%,IF(COUNTIF(Z12:AE12,"Present")=2,20%,IF(COUNTIF(Z12:AE12,"Present")=3,40%,IF(COUNTIF(Z12:AE12,"Present")=4,60%,IF(COUNTIF(Z12:AE12,"Present")=5,80%,IF(COUNTIF(Z12:AE12,"Present")=6,100%,0%)))))) -> 1 | AG12: =COUNTIFS('HQ Fleet Attendance'!$O:$O,Summary!$F$2-1,'HQ Fleet Attendance'!$E:$E,Summary!$Y12) -> 26 | AH12: =RANK(AG12,AG12:AG24) -> 1
A13: joseph_akpan | B13: =_xlfn.MAXIFS(HQ_Fleet_Attendance[data-end_time],HQ_Fleet_Attendance[data-section1-staff],Summary!A13) -> 44859.408 | C13: =_xlfn.MAXIFS('HQ Fleet Attendance'!P:P,'HQ Fleet Attendance'!E:E,Summary!A13) -> 44859 | D13: =IF(COUNTIFS('HQ Fleet Attendance'!Q:Q,Summary!$G$2,'HQ Fleet Attendance'!E:E,Summary!$A13,'HQ Fleet Attendance'!N:N,Summary!D$6)>0,"Present","Absent") -> Present | E13: =IF(COUNTIFS('HQ Fleet Attendance'!Q:Q,Summary!$G$2,'HQ Fleet Attendance'!E:E,Summary!$A13,'HQ Fleet Attendance'!N:N,Summary!E$6)>0,"Present","Absent") -> Present | F13: =IF(COUNTIFS('HQ Fleet Attendance'!Q:Q,Summary!$G$2,'HQ Fleet Attendance'!E:E,Summary!$A13,'HQ Fleet Attendance'!N:N,Summary!F$6)>0,"Present","Absent") -> Absent | G13: =IF(COUNTIFS('HQ Fleet Attendance'!Q:Q,Summary!$G$2,'HQ Fleet Attendance'!E:E,Summary!$A13,'HQ Fleet Attendance'!N:N,Summary!G$6)>0,"Present","Absent") -> Absent | H13: =IF(COUNTIFS('HQ Fleet Attendance'!Q:Q,Summary!$G$2,'HQ Fleet Attendance'!E:E,Summary!$A13,'HQ Fleet Attendance'!N:N,Summary!H$6)>0,"Present","Absent") -> Absent | I13: =IF(COUNTIFS('HQ Fleet Attendance'!Q:Q,Summary!$G$2,'HQ Fleet Attendance'!E:E,Summary!$A13,'HQ Fleet Attendance'!N:N,Summary!I$6)>0,"Present","Absent") -> Absent | J13: =IF(COUNTIF(D13:I13,"Present")=1,10%,IF(COUNTIF(D13:I13,"Present")=2,20%,IF(COUNTIF(D13:I13,"Present")=3,40%,IF(COUNTIF(D13:I13,"Present")=4,60%,IF(COUNTIF(D13:I13,"Present")=5,80%,IF(COUNTIF(D13:I13,"Present")=6,100%,0%)))))) -> 0.2 | K13: =COUNTIFS('HQ Fleet Attendance'!O:O,Summary!$F$2,'HQ Fleet Attendance'!E:E,Summary!A13) -> 19 | L13: =RANK(K13,K13:K25) -> 1 | N13: =A13 -> joseph_akpan | O13: =IF(COUNTIFS('HQ Fleet Attendance'!$Q:$Q,Summary!$G$2-1,'HQ Fleet Attendance'!$E:$E,Summary!$A13,'HQ Fleet Attendance'!$N:$N,Summary!O$6)>0,"Present","Absent") -> Present | P13: =IF(COUNTIFS('HQ Fleet Attendance'!$Q:$Q,Summary!$G$2-1,'HQ Fleet Attendance'!$E:$E,Summary!$A13,'HQ Fleet Attendance'!$N:$N,Summary!P$6)>0,"Present","Absent") -> Present | Q13: =IF(COUNTIFS('HQ Fleet Attendance'!$Q:$Q,Summary!$G$2-1,'HQ Fleet Attendance'!$E:$E,Summary!$A13,'HQ Fleet Attendance'!$N:$N,Summary!Q$6)>0,"Present","Absent") -> Present | R13: =IF(COUNTIFS('HQ Fleet Attendance'!$Q:$Q,Summary!$G$2-1,'HQ Fleet Attendance'!$E:$E,Summary!$A13,'HQ Fleet Attendance'!$N:$N,Summary!R$6)>0,"Present","Absent") -> Present | S13: =IF(COUNTIFS('HQ Fleet Attendance'!$Q:$Q,Summary!$G$2-1,'HQ Fleet Attendance'!$E:$E,Summary!$A13,'HQ Fleet Attendance'!$N:$N,Summary!S$6)>0,"Present","Absent") -> Present | T13: =IF(COUNTIFS('HQ Fleet Attendance'!$Q:$Q,Summary!$G$2-1,'HQ Fleet Attendance'!$E:$E,Summary!$A13,'HQ Fleet Attendance'!$N:$N,Summary!T$6)>0,"Present","Absent") -> Present | U13: =IF(COUNTIF(O13:T13,"Present")=1,10%,IF(COUNTIF(O13:T13,"Present")=2,20%,IF(COUNTIF(O13:T13,"Present")=3,40%,IF(COUNTIF(O13:T13,"Present")=4,60%,IF(COUNTIF(O13:T13,"Present")=5,80%,IF(COUNTIF(O13:T13,"Present")=6,100%,0%)))))) -> 1 | V13: =COUNTIF(O13:T13,"Present") -> 6 | W13: =RANK(V13,V13:V25) -> 1 | Y13: =N13 -> joseph_akpan | Z13: =IF(COUNTIFS('HQ Fleet Attendance'!$O:$O,Summary!$F$2-1,'HQ Fleet Attendance'!$E:$E,Summary!$Y13,'HQ Fleet Attendance'!$N:$N,Summary!Z$6)>0,"Present","Absent") -> Present | AA13: =IF(COUNTIFS('HQ Fleet Attendance'!$O:$O,Summary!$F$2-1,'HQ Fleet Attendance'!$E:$E,Summary!$Y13,'HQ Fleet Attendance'!$N:$N,Summary!AA$6)>0,"Present","Absent") -> Present | AB13: =IF(COUNTIFS('HQ Fleet Attendance'!$O:$O,Summary!$F$2-1,'HQ Fleet Attendance'!$E:$E,Summary!$Y13,'HQ Fleet Attendance'!$N:$N,Summary!AB$6)>0,"Present","Absent") -> Present | AC13: =IF(COUNTIFS('HQ Fleet Attendance'!$O:$O,Summary!$F$2-1,'HQ Fleet Attendance'!$E:$E,Summary!$Y13,'HQ Fleet Attendance'!$N:$N,Summary!AC$6)>0,"Present","Absent") -> Present | AD13: =IF(COUNTIFS('HQ Fleet Attendance'!$O:$O,Summary!$F$2-1,'HQ Fleet Attendance'!$E:$E,Summary!$Y13,'HQ Fleet Attendance'!$N:$N,Summary!AD$6)>0,"Present","Absent") -> Present | AE13: =IF(COUNTIFS('HQ Fleet Attendance'!$O:$O,Summary!$F$2-1,'HQ Fleet Attendance'!$E:$E,Summary!$Y13,'HQ Fleet Attendance'!$N:$N,Summary!AE$6)>0,"Present","Absent") -> Present | AF13: =IF(COUNTIF(Z13:AE13,"Present")=1,10%,IF(COUNTIF(Z13:AE13,"Present")=2,20%,IF(COUNTIF(Z13:AE13,"Present")=3,40%,IF(COUNTIF(Z13:AE13,"Present")=4,60%,IF(COUNTIF(Z13:AE13,"Present")=5,80%,IF(COUNTIF(Z13:AE13,"Present")=6,100%,0%)))))) -> 1 | AG13: =COUNTIFS('HQ Fleet Attendance'!$O:$O,Summary!$F$2-1,'HQ Fleet Attendance'!$E:$E,Summary!$Y13) -> 25 | AH13: =RANK(AG13,AG13:AG25) -> 1
A14: kenedy_onaise | B14: =_xlfn.MAXIFS(HQ_Fleet_Attendance[data-end_time],HQ_Fleet_Attendance[data-section1-staff],Summary!A14) -> 44859.408 | C14: =_xlfn.MAXIFS('HQ Fleet Attendance'!P:P,'HQ Fleet Attendance'!E:E,Summary!A14) -> 44859 | D14: =IF(COUNTIFS('HQ Fleet Attendance'!Q:Q,Summary!$G$2,'HQ Fleet Attendance'!E:E,Summary!$A14,'HQ Fleet Attendance'!N:N,Summary!D$6)>0,"Present","Absent") -> Present | E14: =IF(COUNTIFS('HQ Fleet Attendance'!Q:Q,Summary!$G$2,'HQ Fleet Attendance'!E:E,Summary!$A14,'HQ Fleet Attendance'!N:N,Summary!E$6)>0,"Present","Absent") -> Present | F14: =IF(COUNTIFS('HQ Fleet Attendance'!Q:Q,Summary!$G$2,'HQ Fleet Attendance'!E:E,Summary!$A14,'HQ Fleet Attendance'!N:N,Summary!F$6)>0,"Present","Absent") -> Absent | G14: =IF(COUNTIFS('HQ Fleet Attendance'!Q:Q,Summary!$G$2,'HQ Fleet Attendance'!E:E,Summary!$A14,'HQ Fleet Attendance'!N:N,Summary!G$6)>0,"Present","Absent") -> Absent | H14: =IF(COUNTIFS('HQ Fleet Attendance'!Q:Q,Summary!$G$2,'HQ Fleet Attendance'!E:E,Summary!$A14,'HQ Fleet Attendance'!N:N,Summary!H$6)>0,"Present","Absent") -> Absent | I14: =IF(COUNTIFS('HQ Fleet Attendance'!Q:Q,Summary!$G$2,'HQ Fleet Attendance'!E:E,Summary!$A14,'HQ Fleet Attendance'!N:N,Summary!I$6)>0,"Present","Absent") -> Absent | J14: =IF(COUNTIF(D14:I14,"Present")=1,10%,IF(COUNTIF(D14:I14,"Present")=2,20%,IF(COUNTIF(D14:I14,"Present")=3,40%,IF(COUNTIF(D14:I14,"Present")=4,60%,IF(COUNTIF(D14:I14,"Present")=5,80%,IF(COUNTIF(D14:I14,"Present")=6,100%,0%)))))) -> 0.2 | K14: =COUNTIFS('HQ Fleet Attendance'!O:O,Summary!$F$2,'HQ Fleet Attendance'!E:E,Summary!A14) -> 19 | L14: =RANK(K14,K14:K26) -> 1 | N14: =A14 -> kenedy_onaise | O14: =IF(COUNTIFS('HQ Fleet Attendance'!$Q:$Q,Summary!$G$2-1,'HQ Fleet Attendance'!$E:$E,Summary!$A14,'HQ Fleet Attendance'!$N:$N,Summary!O$6)>0,"Present","Absent") -> Present | P14: =IF(COUNTIFS('HQ Fleet Attendance'!$Q:$Q,Summary!$G$2-1,'HQ Fleet Attendance'!$E:$E,Summary!$A14,'HQ Fleet Attendance'!$N:$N,Summary!P$6)>0,"Present","Absent") -> Present | Q14: =IF(COUNTIFS('HQ Fleet Attendance'!$Q:$Q,Summary!$G$2-1,'HQ Fleet Attendance'!$E:$E,Summary!$A14,'HQ Fleet Attendance'!$N:$N,Summary!Q$6)>0,"Present","Absent") -> Present | R14: =IF(COUNTIFS('HQ Fleet Attendance'!$Q:$Q,Summary!$G$2-1,'HQ Fleet Attendance'!$E:$E,Summary!$A14,'HQ Fleet Attendance'!$N:$N,Summary!R$6)>0,"Present","Absent") -> Present | S14: =IF(COUNTIFS('HQ Fleet Attendance'!$Q:$Q,Summary!$G$2-1,'HQ Fleet Attendance'!$E:$E,Summary!$A14,'HQ Fleet Attendance'!$N:$N,Summary!S$6)>0,"Present","Absent") -> Present | T14: =IF(COUNTIFS('HQ Fleet Attendance'!$Q:$Q,Summary!$G$2-1,'HQ Fleet Attendance'!$E:$E,Summary!$A14,'HQ Fleet Attendance'!$N:$N,Summary!T$6)>0,"Present","Absent") -> Present | U14: =IF(COUNTIF(O14:T14,"Present")=1,10%,IF(COUNTIF(O14:T14,"Present")=2,20%,IF(COUNTIF(O14:T14,"Present")=3,40%,IF(COUNTIF(O14:T14,"Present")=4,60%,IF(COUNTIF(O14:T14,"Present")=5,80%,IF(COUNTIF(O14:T14,"Present")=6,100%,0%)))))) -> 1 | V14: =COUNTIF(O14:T14,"Present") -> 6 | W14: =RANK(V14,V14:V26) -> 1 | Y14: =N14 -> kenedy_onaise | Z14: =IF(COUNTIFS('HQ Fleet Attendance'!$O:$O,Summary!$F$2-1,'HQ Fleet Attendance'!$E:$E,Summary!$Y14,'HQ Fleet Attendance'!$N:$N,Summary!Z$6)>0,"Present","Absent") -> Present | AA14: =IF(COUNTIFS('HQ Fleet Attendance'!$O:$O,Summary!$F$2-1,'HQ Fleet Attendance'!$E:$E,Summary!$Y14,'HQ Fleet Attendance'!$N:$N,Summary!AA$6)>0,"Present","Absent") -> Present | AB14: =IF(COUNTIFS('HQ Fleet Attendance'!$O:$O,Summary!$F$2-1,'HQ Fleet Attendance'!$E:$E,Summary!$Y14,'HQ Fleet Attendance'!$N:$N,Summary!AB$6)>0,"Present","Absent") -> Present | AC14: =IF(COUNTIFS('HQ Fleet Attendance'!$O:$O,Summary!$F$2-1,'HQ Fleet Attendance'!$E:$E,Summary!$Y14,'HQ Fleet Attendance'!$N:$N,Summary!AC$6)>0,"Present","Absent") -> Present | AD14: =IF(COUNTIFS('HQ Fleet Attendance'!$O:$O,Summary!$F$2-1,'HQ Fleet Attendance'!$E:$E,Summary!$Y14,'HQ Fleet Attendance'!$N:$N,Summary!AD$6)>0,"Present","Absent") -> Present | AE14: =IF(COUNTIFS('HQ Fleet Attendance'!$O:$O,Summary!$F$2-1,'HQ Fleet Attendance'!$E:$E,Summary!$Y14,'HQ Fleet Attendance'!$N:$N,Summary!AE$6)>0,"Present","Absent") -> Present | AF14: =IF(COUNTIF(Z14:AE14,"Present")=1,10%,IF(COUNTIF(Z14:AE14,"Present")=2,20%,IF(COUNTIF(Z14:AE14,"Present")=3,40%,IF(COUNTIF(Z14:AE14,"Present")=4,60%,IF(COUNTIF(Z14:AE14,"Present")=5,80%,IF(COUNTIF(Z14:AE14,"Present")=6,100%,0%)))))) -> 1 | AG14: =COUNTIFS('HQ Fleet Attendance'!$O:$O,Summary!$F$2-1,'HQ Fleet Attendance'!$E:$E,Summary!$Y14) -> 21 | AH14: =RANK(AG14,AG14:AG26) -> 4
A15: michael_omotosho | B15: =_xlfn.MAXIFS(HQ_Fleet_Attendance[data-end_time],HQ_Fleet_Attendance[data-section1-staff],Summary!A15) -> 44859.409 | C15: =_xlfn.MAXIFS('HQ Fleet Attendance'!P:P,'HQ Fleet Attendance'!E:E,Summary!A15) -> 44859 | D15: =IF(COUNTIFS('HQ Fleet Attendance'!Q:Q,Summary!$G$2,'HQ Fleet Attendance'!E:E,Summary!$A15,'HQ Fleet Attendance'!N:N,Summary!D$6)>0,"Present","Absent") -> Present | E15: =IF(COUNTIFS('HQ Fleet Attendance'!Q:Q,Summary!$G$2,'HQ Fleet Attendance'!E:E,Summary!$A15,'HQ Fleet Attendance'!N:N,Summary!E$6)>0,"Present","Absent") -> Present | F15: =IF(COUNTIFS('HQ Fleet Attendance'!Q:Q,Summary!$G$2,'HQ Fleet Attendance'!E:E,Summary!$A15,'HQ Fleet Attendance'!N:N,Summary!F$6)>0,"Present","Absent") -> Absent | G15: =IF(COUNTIFS('HQ Fleet Attendance'!Q:Q,Summary!$G$2,'HQ Fleet Attendance'!E:E,Summary!$A15,'HQ Fleet Attendance'!N:N,Summary!G$6)>0,"Present","Absent") -> Absent | H15: =IF(COUNTIFS('HQ Fleet Attendance'!Q:Q,Summary!$G$2,'HQ Fleet Attendance'!E:E,Summary!$A15,'HQ Fleet Attendance'!N:N,Summary!H$6)>0,"Present","Absent") -> Absent | I15: =IF(COUNTIFS('HQ Fleet Attendance'!Q:Q,Summary!$G$2,'HQ Fleet Attendance'!E:E,Summary!$A15,'HQ Fleet Attendance'!N:N,Summary!I$6)>0,"Present","Absent") -> Absent | J15: =IF(COUNTIF(D15:I15,"Present")=1,10%,IF(COUNTIF(D15:I15,"Present")=2,20%,IF(COUNTIF(D15:I15,"Present")=3,40%,IF(COUNTIF(D15:I15,"Present")=4,60%,IF(COUNTIF(D15:I15,"Present")=5,80%,IF(COUNTIF(D15:I15,"Present")=6,100%,0%)))))) -> 0.2 | K15: =COUNTIFS('HQ Fleet Attendance'!O:O,Summary!$F$2,'HQ Fleet Attendance'!E:E,Summary!A15) -> 15 | L15: =RANK(K15,K15:K27) -> 3 | N15: =A15 -> michael_omotosho | O15: =IF(COUNTIFS('HQ Fleet Attendance'!$Q:$Q,Summary!$G$2-1,'HQ Fleet Attendance'!$E:$E,Summary!$A15,'HQ Fleet Attendance'!$N:$N,Summary!O$6)>0,"Present","Absent") -> Present | P15: =IF(COUNTIFS('HQ Fleet Attendance'!$Q:$Q,Summary!$G$2-1,'HQ Fleet Attendance'!$E:$E,Summary!$A15,'HQ Fleet Attendance'!$N:$N,Summary!P$6)>0,"Present","Absent") -> Present | Q15: =IF(COUNTIFS('HQ Fleet Attendance'!$Q:$Q,Summary!$G$2-1,'HQ Fleet Attendance'!$E:$E,Summary!$A15,'HQ Fleet Attendance'!$N:$N,Summary!Q$6)>0,"Present","Absent") -> Present | R15: =IF(COUNTIFS('HQ Fleet Attendance'!$Q:$Q,Summary!$G$2-1,'HQ Fleet Attendance'!$E:$E,Summary!$A15,'HQ Fleet Attendance'!$N:$N,Summary!R$6)>0,"Present","Absent") -> Present | S15: =IF(COUNTIFS('HQ Fleet Attendance'!$Q:$Q,Summary!$G$2-1,'HQ Fleet Attendance'!$E:$E,Summary!$A15,'HQ Fleet Attendance'!$N:$N,Summary!S$6)>0,"Present","Absent") -> Present | T15: =IF(COUNTIFS('HQ Fleet Attendance'!$Q:$Q,Summary!$G$2-1,'HQ Fleet Attendance'!$E:$E,Summary!$A15,'HQ Fleet Attendance'!$N:$N,Summary!T$6)>0,"Present","Absent") -> Absent | U15: =IF(COUNTIF(O15:T15,"Present")=1,10%,IF(COUNTIF(O15:T15,"Present")=2,20%,IF(COUNTIF(O15:T15,"Present")=3,40%,IF(COUNTIF(O15:T15,"Present")=4,60%,IF(COUNTIF(O15:T15,"Present")=5,80%,IF(COUNTIF(O15:T15,"Present")=6,100%,0%)))))) -> 0.8 | V15: =COUNTIF(O15:T15,"Present") -> 5 | W15: =RANK(V15,V15:V27) -> 4 | Y15: =N15 -> michael_omotosho | Z15: =IF(COUNTIFS('HQ Fleet Attendance'!$O:$O,Summary!$F$2-1,'HQ Fleet Attendance'!$E:$E,Summary!$Y15,'HQ Fleet Attendance'!$N:$N,Summary!Z$6)>0,"Present","Absent") -> Present | AA15: =IF(COUNTIFS('HQ Fleet Attendance'!$O:$O,Summary!$F$2-1,'HQ Fleet Attendance'!$E:$E,Summary!$Y15,'HQ Fleet Attendance'!$N:$N,Summary!AA$6)>0,"Present","Absent") -> Present | AB15: =IF(COUNTIFS('HQ Fleet Attendance'!$O:$O,Summary!$F$2-1,'HQ Fleet Attendance'!$E:$E,Summary!$Y15,'HQ Fleet Attendance'!$N:$N,Summary!AB$6)>0,"Present","Absent") -> Present | AC15: =IF(COUNTIFS('HQ Fleet Attendance'!$O:$O,Summary!$F$2-1,'HQ Fleet Attendance'!$E:$E,Summary!$Y15,'HQ Fleet Attendance'!$N:$N,Summary!AC$6)>0,"Present","Absent") -> Present | AD15: =IF(COUNTIFS('HQ Fleet Attendance'!$O:$O,Summary!$F$2-1,'HQ Fleet Attendance'!$E:$E,Summary!$Y15,'HQ Fleet Attendance'!$N:$N,Summary!AD$6)>0,"Present","Absent") -> Present | AE15: =IF(COUNTIFS('HQ Fleet Attendance'!$O:$O,Summary!$F$2-1,'HQ Fleet Attendance'!$E:$E,Summary!$Y15,'HQ Fleet Attendance'!$N:$N,Summary!AE$6)>0,"Present","Absent") -> Absent | AF15: =IF(COUNTIF(Z15:AE15,"Present")=1,10%,IF(COUNTIF(Z15:AE15,"Present")=2,20%,IF(COUNTIF(Z15:AE15,"Present")=3,40%,IF(COUNTIF(Z15:AE15,"Present")=4,60%,IF(COUNTIF(Z15:AE15,"Present")=5,80%,IF(COUNTIF(Z15:AE15,"Present")=6,100%,0%)))))) -> 0.8 | AG15: =COUNTIFS('HQ Fleet Attendance'!$O:$O,Summary!$F$2-1,'HQ Fleet Attendance'!$E:$E,Summary!$Y15) -> 21 | AH15: =RANK(AG15,AG15:AG27) -> 4
A16: ogunlade_samuel_tope | B16: =_xlfn.MAXIFS(HQ_Fleet_Attendance[data-end_time],HQ_Fleet_Attendance[data-section1-staff],Summary!A16) -> 44859.409 | C16: =_xlfn.MAXIFS('HQ Fleet Attendance'!P:P,'HQ Fleet Attendance'!E:E,Summary!A16) -> 44859 | D16: =IF(COUNTIFS('HQ Fleet Attendance'!Q:Q,Summary!$G$2,'HQ Fleet Attendance'!E:E,Summary!$A16,'HQ Fleet Attendance'!N:N,Summary!D$6)>0,"Present","Absent") -> Present | E16: =IF(COUNTIFS('HQ Fleet Attendance'!Q:Q,Summary!$G$2,'HQ Fleet Attendance'!E:E,Summary!$A16,'HQ Fleet Attendance'!N:N,Summary!E$6)>0,"Present","Absent") -> Present | F16: =IF(COUNTIFS('HQ Fleet Attendance'!Q:Q,Summary!$G$2,'HQ Fleet Attendance'!E:E,Summary!$A16,'HQ Fleet Attendance'!N:N,Summary!F$6)>0,"Present","Absent") -> Absent | G16: =IF(COUNTIFS('HQ Fleet Attendance'!Q:Q,Summary!$G$2,'HQ Fleet Attendance'!E:E,Summary!$A16,'HQ Fleet Attendance'!N:N,Summary!G$6)>0,"Present","Absent") -> Absent | H16: =IF(COUNTIFS('HQ Fleet Attendance'!Q:Q,Summary!$G$2,'HQ Fleet Attendance'!E:E,Summary!$A16,'HQ Fleet Attendance'!N:N,Summary!H$6)>0,"Present","Absent") -> Absent | I16: =IF(COUNTIFS('HQ Fleet Attendance'!Q:Q,Summary!$G$2,'HQ Fleet Attendance'!E:E,Summary!$A16,'HQ Fleet Attendance'!N:N,Summary!I$6)>0,"Present","Absent") -> Absent | J16: =IF(COUNTIF(D16:I16,"Present")=1,10%,IF(COUNTIF(D16:I16,"Present")=2,20%,IF(COUNTIF(D16:I16,"Present")=3,40%,IF(COUNTIF(D16:I16,"Present")=4,60%,IF(COUNTIF(D16:I16,"Present")=5,80%,IF(COUNTIF(D16:I16,"Present")=6,100%,0%)))))) -> 0.2 | K16: =COUNTIFS('HQ Fleet Attendance'!O:O,Summary!$F$2,'HQ Fleet Attendance'!E:E,Summary!A16) -> 14 | L16: =RANK(K16,K16:K28) -> 3 | N16: =A16 -> ogunlade_samuel_tope | O16: =IF(COUNTIFS('HQ Fleet Attendance'!$Q:$Q,Summary!$G$2-1,'HQ Fleet Attendance'!$E:$E,Summary!$A16,'HQ Fleet Attendance'!$N:$N,Summary!O$6)>0,"Present","Absent") -> Present | P16: =IF(COUNTIFS('HQ Fleet Attendance'!$Q:$Q,Summary!$G$2-1,'HQ Fleet Attendance'!$E:$E,Summary!$A16,'HQ Fleet Attendance'!$N:$N,Summary!P$6)>0,"Present","Absent") -> Present | Q16: =IF(COUNTIFS('HQ Fleet Attendance'!$Q:$Q,Summary!$G$2-1,'HQ Fleet Attendance'!$E:$E,Summary!$A16,'HQ Fleet Attendance'!$N:$N,Summary!Q$6)>0,"Present","Absent") -> Present | R16: =IF(COUNTIFS('HQ Fleet Attendance'!$Q:$Q,Summary!$G$2-1,'HQ Fleet Attendance'!$E:$E,Summary!$A16,'HQ Fleet Attendance'!$N:$N,Summary!R$6)>0,"Present","Absent") -> Present | S16: =IF(COUNTIFS('HQ Fleet Attendance'!$Q:$Q,Summary!$G$2-1,'HQ Fleet Attendance'!$E:$E,Summary!$A16,'HQ Fleet Attendance'!$N:$N,Summary!S$6)>0,"Present","Absent") -> Present | T16: =IF(COUNTIFS('HQ Fleet Attendance'!$Q:$Q,Summary!$G$2-1,'HQ Fleet Attendance'!$E:$E,Summary!$A16,'HQ Fleet Attendance'!$N:$N,Summary!T$6)>0,"Present","Absent") -> Present | U16: =IF(COUNTIF(O16:T16,"Present")=1,10%,IF(COUNTIF(O16:T16,"Present")=2,20%,IF(COUNTIF(O16:T16,"Present")=3,40%,IF(COUNTIF(O16:T16,"Present")=4,60%,IF(COUNTIF(O16:T16,"Present")=5,80%,IF(COUNTIF(O16:T16,"Present")=6,100%,0%)))))) -> 1 | V16: =COUNTIF(O16:T16,"Present") -> 6 | W16: =RANK(V16,V16:V28) -> 1 | Y16: =N16 -> ogunlade_samuel_tope | Z16: =IF(COUNTIFS('HQ Fleet Attendance'!$O:$O,Summary!$F$2-1,'HQ Fleet Attendance'!$E:$E,Summary!$Y16,'HQ Fleet Attendance'!$N:$N,Summary!Z$6)>0,"Present","Absent") -> Present | AA16: =IF(COUNTIFS('HQ Fleet Attendance'!$O:$O,Summary!$F$2-1,'HQ Fleet Attendance'!$E:$E,Summary!$Y16,'HQ Fleet Attendance'!$N:$N,Summary!AA$6)>0,"Present","Absent") -> Present | AB16: =IF(COUNTIFS('HQ Fleet Attendance'!$O:$O,Summary!$F$2-1,'HQ Fleet Attendance'!$E:$E,Summary!$Y16,'HQ Fleet Attendance'!$N:$N,Summary!AB$6)>0,"Present","Absent") -> Present | AC16: =IF(COUNTIFS('HQ Fleet Attendance'!$O:$O,Summary!$F$2-1,'HQ Fleet Attendance'!$E:$E,Summary!$Y16,'HQ Fleet Attendance'!$N:$N,Summary!AC$6)>0,"Present","Absent") -> Present | AD16: =IF(COUNTIFS('HQ Fleet Attendance'!$O:$O,Summary!$F$2-1,'HQ Fleet Attendance'!$E:$E,Summary!$Y16,'HQ Fleet Attendance'!$N:$N,Summary!AD$6)>0,"Present","Absent") -> Present | AE16: =IF(COUNTIFS('HQ Fleet Attendance'!$O:$O,Summary!$F$2-1,'HQ Fleet Attendance'!$E:$E,Summary!$Y16,'HQ Fleet Attendance'!$N:$N,Summary!AE$6)>0,"Present","Absent") -> Present | AF16: =IF(COUNTIF(Z16:AE16,"Present")=1,10%,IF(COUNTIF(Z16:AE16,"Present")=2,20%,IF(COUNTIF(Z16:AE16,"Present")=3,40%,IF(COUNTIF(Z16:AE16,"Present")=4,60%,IF(COUNTIF(Z16:AE16,"Present")=5,80%,IF(COUNTIF(Z16:AE16,"Present")=6,100%,0%)))))) -> 1 | AG16: =COUNTIFS('HQ Fleet Attendance'!$O:$O,Summary!$F$2-1,'HQ Fleet Attendance'!$E:$E,Summary!$Y16) -> 25 | AH16: =RANK(AG16,AG16:AG28) -> 1
A17: oluwaseun_corper | B17: =_xlfn.MAXIFS(HQ_Fleet_Attendance[data-end_time],HQ_Fleet_Attendance[data-section1-staff],Summary!A17) -> 44859.409 | C17: =_xlfn.MAXIFS('HQ Fleet Attendance'!P:P,'HQ Fleet Attendance'!E:E,Summary!A17) -> 44859 | D17: =IF(COUNTIFS('HQ Fleet Attendance'!Q:Q,Summary!$G$2,'HQ Fleet Attendance'!E:E,Summary!$A17,'HQ Fleet Attendance'!N:N,Summary!D$6)>0,"Present","Absent") -> Present | E17: =IF(COUNTIFS('HQ Fleet Attendance'!Q:Q,Summary!$G$2,'HQ Fleet Attendance'!E:E,Summary!$A17,'HQ Fleet Attendance'!N:N,Summary!E$6)>0,"Present","Absent") -> Present | F17: =IF(COUNTIFS('HQ Fleet Attendance'!Q:Q,Summary!$G$2,'HQ Fleet Attendance'!E:E,Summary!$A17,'HQ Fleet Attendance'!N:N,Summary!F$6)>0,"Present","Absent") -> Absent | G17: =IF(COUNTIFS('HQ Fleet Attendance'!Q:Q,Summary!$G$2,'HQ Fleet Attendance'!E:E,Summary!$A17,'HQ Fleet Attendance'!N:N,Summary!G$6)>0,"Present","Absent") -> Absent | H17: =IF(COUNTIFS('HQ Fleet Attendance'!Q:Q,Summary!$G$2,'HQ Fleet Attendance'!E:E,Summary!$A17,'HQ Fleet Attendance'!N:N,Summary!H$6)>0,"Present","Absent") -> Absent | I17: =IF(COUNTIFS('HQ Fleet Attendance'!Q:Q,Summary!$G$2,'HQ Fleet Attendance'!E:E,Summary!$A17,'HQ Fleet Attendance'!N:N,Summary!I$6)>0,"Present","Absent") -> Absent | J17: =IF(COUNTIF(D17:I17,"Present")=1,10%,IF(COUNTIF(D17:I17,"Present")=2,20%,IF(COUNTIF(D17:I17,"Present")=3,40%,IF(COUNTIF(D17:I17,"Present")=4,60%,IF(COUNTIF(D17:I17,"Present")=5,80%,IF(COUNTIF(D17:I17,"Present")=6,100%,0%)))))) -> 0.2 | K17: =COUNTIFS('HQ Fleet Attendance'!O:O,Summary!$F$2,'HQ Fleet Attendance'!E:E,Summary!A17) -> 11 | L17: =RANK(K17,K17:K29) -> 3 | N17: =A17 -> oluwaseun_corper | O17: =IF(COUNTIFS('HQ Fleet Attendance'!$Q:$Q,Summary!$G$2-1,'HQ Fleet Attendance'!$E:$E,Summary!$A17,'HQ Fleet Attendance'!$N:$N,Summary!O$6)>0,"Present","Absent") -> Present | P17: =IF(COUNTIFS('HQ Fleet Attendance'!$Q:$Q,Summary!$G$2-1,'HQ Fleet Attendance'!$E:$E,Summary!$A17,'HQ Fleet Attendance'!$N:$N,Summary!P$6)>0,"Present","Absent") -> Present | Q17: =IF(COUNTIFS('HQ Fleet Attendance'!$Q:$Q,Summary!$G$2-1,'HQ Fleet Attendance'!$E:$E,Summary!$A17,'HQ Fleet Attendance'!$N:$N,Summary!Q$6)>0,"Present","Absent") -> Absent | R17: =IF(COUNTIFS('HQ Fleet Attendance'!$Q:$Q,Summary!$G$2-1,'HQ Fleet Attendance'!$E:$E,Summary!$A17,'HQ Fleet Attendance'!$N:$N,Summary!R$6)>0,"Present","Absent") -> Present | S17: =IF(COUNTIFS('HQ Fleet Attendance'!$Q:$Q,Summary!$G$2-1,'HQ Fleet Attendance'!$E:$E,Summary!$A17,'HQ Fleet Attendance'!$N:$N,Summary!S$6)>0,"Present","Absent") -> Present | T17: =IF(COUNTIFS('HQ Fleet Attendance'!$Q:$Q,Summary!$G$2-1,'HQ Fleet Attendance'!$E:$E,Summary!$A17,'HQ Fleet Attendance'!$N:$N,Summary!T$6)>0,"Present","Absent") -> Absent | U17: =IF(COUNTIF(O17:T17,"Present")=1,10%,IF(COUNTIF(O17:T17,"Present")=2,20%,IF(COUNTIF(O17:T17,"Present")=3,40%,IF(COUNTIF(O17:T17,"Present")=4,60%,IF(COUNTIF(O17:T17,"Present")=5,80%,IF(COUNTIF(O17:T17,"Present")=6,100%,0%)))))) -> 0.6 | V17: =COUNTIF(O17:T17,"Present") -> 4 | W17: =RANK(V17,V17:V29) -> 3 | Y17: =N17 -> oluwaseun_corper | Z17: =IF(COUNTIFS('HQ Fleet Attendance'!$O:$O,Summary!$F$2-1,'HQ Fleet Attendance'!$E:$E,Summary!$Y17,'HQ Fleet Attendance'!$N:$N,Summary!Z$6)>0,"Present","Absent") -> Present | AA17: =IF(COUNTIFS('HQ Fleet Attendance'!$O:$O,Summary!$F$2-1,'HQ Fleet Attendance'!$E:$E,Summary!$Y17,'HQ Fleet Attendance'!$N:$N,Summary!AA$6)>0,"Present","Absent") -> Present | AB17: =IF(COUNTIFS('HQ Fleet Attendance'!$O:$O,Summary!$F$2-1,'HQ Fleet Attendance'!$E:$E,Summary!$Y17,'HQ Fleet Attendance'!$N:$N,Summary!AB$6)>0,"Present","Absent") -> Absent | AC17: =IF(COUNTIFS('HQ Fleet Attendance'!$O:$O,Summary!$F$2-1,'HQ Fleet Attendance'!$E:$E,Summary!$Y17,'HQ Fleet Attendance'!$N:$N,Summary!AC$6)>0,"Present","Absent") -> Present | AD17: =IF(COUNTIFS('HQ Fleet Attendance'!$O:$O,Summary!$F$2-1,'HQ Fleet Attendance'!$E:$E,Summary!$Y17,'HQ Fleet Attendance'!$N:$N,Summary!AD$6)>0,"Present","Absent") -> Present | AE17: =IF(COUNTIFS('HQ Fleet Attendance'!$O:$O,Summary!$F$2-1,'HQ Fleet Attendance'!$E:$E,Summary!$Y17,'HQ Fleet Attendance'!$N:$N,Summary!AE$6)>0,"Present","Absent") -> Absent | AF17: =IF(COUNTIF(Z17:AE17,"Present")=1,10%,IF(COUNTIF(Z17:AE17,"Present")=2,20%,IF(COUNTIF(Z17:AE17,"Present")=3,40%,IF(COUNTIF(Z17:AE17,"Present")=4,60%,IF(COUNTIF(Z17:AE17,"Present")=5,80%,IF(COUNTIF(Z17:AE17,"Present")=6,100%,0%)))))) -> 0.6 | AG17: =COUNTIFS('HQ Fleet Attendance'!$O:$O,Summary!$F$2-1,'HQ Fleet Attendance'!$E:$E,Summary!$Y17) -> 14 | AH17: =RANK(AG17,AG17:AG29) -> 3
A18: paul_oyelaran | B18: =_xlfn.MAXIFS(HQ_Fleet_Attendance[data-end_time],HQ_Fleet_Attendance[data-section1-staff],Summary!A18) -> 44859.408 | C18: =_xlfn.MAXIFS('HQ Fleet Attendance'!P:P,'HQ Fleet Attendance'!E:E,Summary!A18) -> 44859 | D18: =IF(COUNTIFS('HQ Fleet Attendance'!Q:Q,Summary!$G$2,'HQ Fleet Attendance'!E:E,Summary!$A18,'HQ Fleet Attendance'!N:N,Summary!D$6)>0,"Present","Absent") -> Present | E18: =IF(COUNTIFS('HQ Fleet Attendance'!Q:Q,Summary!$G$2,'HQ Fleet Attendance'!E:E,Summary!$A18,'HQ Fleet Attendance'!N:N,Summary!E$6)>0,"Present","Absent") -> Present | F18: =IF(COUNTIFS('HQ Fleet Attendance'!Q:Q,Summary!$G$2,'HQ Fleet Attendance'!E:E,Summary!$A18,'HQ Fleet Attendance'!N:N,Summary!F$6)>0,"Present","Absent") -> Absent | G18: =IF(COUNTIFS('HQ Fleet Attendance'!Q:Q,Summary!$G$2,'HQ Fleet Attendance'!E:E,Summary!$A18,'HQ Fleet Attendance'!N:N,Summary!G$6)>0,"Present","Absent") -> Absent | H18: =IF(COUNTIFS('HQ Fleet Attendance'!Q:Q,Summary!$G$2,'HQ Fleet Attendance'!E:E,Summary!$A18,'HQ Fleet Attendance'!N:N,Summary!H$6)>0,"Present","Absent") -> Absent | I18: =IF(COUNTIFS('HQ Fleet Attendance'!Q:Q,Summary!$G$2,'HQ Fleet Attendance'!E:E,Summary!$A18,'HQ Fleet Attendance'!N:N,Summary!I$6)>0,"Present","Absent") -> Absent | J18: =IF(COUNTIF(D18:I18,"Present")=1,10%,IF(COUNTIF(D18:I18,"Present")=2,20%,IF(COUNTIF(D18:I18,"Present")=3,40%,IF(COUNTIF(D18:I18,"Present")=4,60%,IF(COUNTIF(D18:I18,"Present")=5,80%,IF(COUNTIF(D18:I18,"Present")=6,100%,0%)))))) -> 0.2 | K18: =COUNTIFS('HQ Fleet Attendance'!O:O,Summary!$F$2,'HQ Fleet Attendance'!E:E,Summary!A18) -> 19 | L18: =RANK(K18,K18:K30) -> 1 | N18: =A18 -> paul_oyelaran | O18: =IF(COUNTIFS('HQ Fleet Attendance'!$Q:$Q,Summary!$G$2-1,'HQ Fleet Attendance'!$E:$E,Summary!$A18,'HQ Fleet Attendance'!$N:$N,Summary!O$6)>0,"Present","Absent") -> Present | P18: =IF(COUNTIFS('HQ Fleet Attendance'!$Q:$Q,Summary!$G$2-1,'HQ Fleet Attendance'!$E:$E,Summary!$A18,'HQ Fleet Attendance'!$N:$N,Summary!P$6)>0,"Present","Absent") -> Present | Q18: =IF(COUNTIFS('HQ Fleet Attendance'!$Q:$Q,Summary!$G$2-1,'HQ Fleet Attendance'!$E:$E,Summary!$A18,'HQ Fleet Attendance'!$N:$N,Summary!Q$6)>0,"Present","Absent") -> Present | R18: =IF(COUNTIFS('HQ Fleet Attendance'!$Q:$Q,Summary!$G$2-1,'HQ Fleet Attendance'!$E:$E,Summary!$A18,'HQ Fleet Attendance'!$N:$N,Summary!R$6)>0,"Present","Absent") -> Present | S18: =IF(COUNTIFS('HQ Fleet Attendance'!$Q:$Q,Summary!$G$2-1,'HQ Fleet Attendance'!$E:$E,Summary!$A18,'HQ Fleet Attendance'!$N:$N,Summary!S$6)>0,"Present","Absent") -> Present | T18: =IF(COUNTIFS('HQ Fleet Attendance'!$Q:$Q,Summary!$G$2-1,'HQ Fleet Attendance'!$E:$E,Summary!$A18,'HQ Fleet Attendance'!$N:$N,Summary!T$6)>0,"Present","Absent") -> Present | U18: =IF(COUNTIF(O18:T18,"Present")=1,10%,IF(COUNTIF(O18:T18,"Present")=2,20%,IF(COUNTIF(O18:T18,"Present")=3,40%,IF(COUNTIF(O18:T18,"Present")=4,60%,IF(COUNTIF(O18:T18,"Present")=5,80%,IF(COUNTIF(O18:T18,"Present")=6,100%,0%)))))) -> 1 | V18: =COUNTIF(O18:T18,"Present") -> 6 | W18: =RANK(V18,V18:V30) -> 1 | Y18: =N18 -> paul_oyelaran | Z18: =IF(COUNTIFS('HQ Fleet Attendance'!$O:$O,Summary!$F$2-1,'HQ Fleet Attendance'!$E:$E,Summary!$Y18,'HQ Fleet Attendance'!$N:$N,Summary!Z$6)>0,"Present","Absent") -> Present | AA18: =IF(COUNTIFS('HQ Fleet Attendance'!$O:$O,Summary!$F$2-1,'HQ Fleet Attendance'!$E:$E,Summary!$Y18,'HQ Fleet Attendance'!$N:$N,Summary!AA$6)>0,"Present","Absent") -> Present | AB18: =IF(COUNTIFS('HQ Fleet Attendance'!$O:$O,Summary!$F$2-1,'HQ Fleet Attendance'!$E:$E,Summary!$Y18,'HQ Fleet Attendance'!$N:$N,Summary!AB$6)>0,"Present","Absent") -> Present | AC18: =IF(COUNTIFS('HQ Fleet Attendance'!$O:$O,Summary!$F$2-1,'HQ Fleet Attendance'!$E:$E,Summary!$Y18,'HQ Fleet Attendance'!$N:$N,Summary!AC$6)>0,"Present","Absent") -> Present | AD18: =IF(COUNTIFS('HQ Fleet Attendance'!$O:$O,Summary!$F$2-1,'HQ Fleet Attendance'!$E:$E,Summary!$Y18,'HQ Fleet Attendance'!$N:$N,Summary!AD$6)>0,"Present","Absent") -> Present | AE18: =IF(COUNTIFS('HQ Fleet Attendance'!$O:$O,Summary!$F$2-1,'HQ Fleet Attendance'!$E:$E,Summary!$Y18,'HQ Fleet Attendance'!$N:$N,Summary!AE$6)>0,"Present","Absent") -> Present | AF18: =IF(COUNTIF(Z18:AE18,"Present")=1,10%,IF(COUNTIF(Z18:AE18,"Present")=2,20%,IF(COUNTIF(Z18:AE18,"Present")=3,40%,IF(COUNTIF(Z18:AE18,"Present")=4,60%,IF(COUNTIF(Z18:AE18,"Present")=5,80%,IF(COUNTIF(Z18:AE18,"Present")=6,100%,0%)))))) -> 1 | AG18: =COUNTIFS('HQ Fleet Attendance'!$O:$O,Summary!$F$2-1,'HQ Fleet Attendance'!$E:$E,Summary!$Y18) -> 24 | AH18: =RANK(AG18,AG18:AG30) -> 1
